<?xml version="1.0" encoding="utf-8"?>

<robot xmlns:xacro="http://www.ros.org/wiki/xacro" name="w2_body">

    <xacro:macro name="w2_body">

        <link name="base_footprint">
        </link>

        <link name="base_link">
            <inertial>
                <origin xyz="-0.00183994912012901 0.000718384784481402 0.040896257051146"
                    rpy="0 0 0" />
                <mass value="2.11446326748896" />
                <inertia ixx="0.0172522550977486" ixy="0.000112962512291742"
                    ixz="0.00215471233797688"
                    iyy="0.0214703513066925" iyz="-3.60344762320202E-05" izz="0.0232865128652866" />
            </inertial>
            <visual>
                <origin xyz="0 0 0" rpy="0 0 0" />
                <geometry>
                    <mesh filename="package://upros_description/meshes/W2C/base_link.STL" />
                </geometry>
                <material name="">
                    <color rgba="0.898039215686275 0.917647058823529 0.929411764705882 1" />
                </material>
            </visual>
            <collision>
                <origin xyz="0 0 0" rpy="0 0 0" />
                <geometry>
                    <mesh filename="package://upros_description/meshes/W2C/base_link.STL" />
                </geometry>
            </collision>
        </link>
        <joint name="base_footprint_joint" type="fixed">
            <parent link="base_footprint" />
            <child link="base_link" />
        </joint>

        <link name="wheel_L_link">
            <inertial>
                <origin xyz="-3.78770996320736E-07 -0.013414250594195 4.81266645289274E-07"
                    rpy="0 0 0" />
                <mass value="0.337836569375269" />
                <inertia ixx="0.000278270805900081" ixy="1.29138084160578E-09"
                    ixz="1.09699819030228E-09" iyy="0.000496405737651082"
                    iyz="-1.64156177606385E-09"
                    izz="0.000278271727426874" />
            </inertial>
            <visual>
                <origin xyz="0 0 0" rpy="0 0 0" />
                <geometry>
                    <mesh filename="package://upros_description/meshes/W2C/wheel_L_link.STL" />
                </geometry>
                <material name="">
                    <color rgba="0.752941176470588 0.752941176470588 0.752941176470588 1" />
                </material>
            </visual>
            <collision>
                <origin xyz="0 0 0" rpy="0 0 0" />
                <geometry>
                    <mesh filename="package://upros_description/meshes/W2C/wheel_L_link.STL" />
                </geometry>
            </collision>
        </link>
        <joint name="wheel_L_joint" type="continuous">
            <origin xyz="0 0.1215 -0.02" rpy="0 0 0" />
            <parent link="base_link" />
            <child link="wheel_L_link" />
            <axis xyz="0 1 0" />
        </joint>

        <link name="wheel_R_link">
            <inertial>
                <origin xyz="-5.54575135339762E-07 0.013414250594195 2.59868179624395E-07"
                    rpy="0 0 0" />
                <mass value="0.337836569375269" />
                <inertia ixx="0.000278271195902002" ixy="-1.89148049635397E-09"
                    ixz="1.18772924132671E-09" iyy="0.000496405737651082" iyz="8.85827903470683E-10"
                    izz="0.000278271337424954" />
            </inertial>
            <visual>
                <origin xyz="0 0 0" rpy="0 0 0" />
                <geometry>
                    <mesh filename="package://upros_description/meshes/W2C/wheel_R_link.STL" />
                </geometry>
                <material name="">
                    <color rgba="0.752941176470588 0.752941176470588 0.752941176470588 1" />
                </material>
            </visual>
            <collision>
                <origin xyz="0 0 0" rpy="0 0 0" />
                <geometry>
                    <mesh filename="package://upros_description/meshes/W2C/wheel_R_link.STL" />
                </geometry>
            </collision>
        </link>
        <joint name="wheel_R_joint" type="continuous">
            <origin xyz="0 -0.1215 -0.02" rpy="0 0 0" />
            <parent link="base_link" />
            <child link="wheel_R_link" />
            <axis xyz="0 1 0" />
        </joint>

        <link name="front_Link">
            <inertial>
                <origin xyz="0 0 0" rpy="0 0 0" />
                <mass value="0.0063074121665526" />
                <inertia ixx="3.34755925557046E-07" ixy="-1.45392467961487E-22"
                    ixz="2.42001994301979E-24" iyy="4.93530086138426E-07" iyz="6.44209161389679E-25"
                    izz="3.34755925557046E-07" />
            </inertial>
            <visual>
                <origin xyz="0 0 0" rpy="0 0 0" />
                <geometry>
                    <mesh filename="package://upros_description/meshes/W2C/wheel_B_Link.STL" />
                </geometry>
                <material name="">
                    <color rgba="0.752941176470588 1 1 1" />
                </material>
            </visual>
            <collision>
                <origin xyz="0 0 0" rpy="0 0 0" />
                <geometry>
                    <mesh filename="package://upros_description/meshes/W2C/wheel_B_Link.STL" />
                </geometry>
            </collision>
        </link>
        <joint name="front_joint" type="continuous">
            <origin xyz="0.0859999999999999 0 -0.0575" rpy="0 0 0" />
            <parent link="base_link" />
            <child link="front_Link" />
            <axis xyz="1 1 1" />
        </joint>

        <link name="back_Link">
            <inertial>
                <origin xyz="0 0 0" rpy="0 0 0" />
                <mass value="0.0063074121665526" />
                <inertia ixx="3.34755925557046E-07" ixy="-1.45392467961487E-22"
                    ixz="2.42001994301979E-24" iyy="4.93530086138426E-07" iyz="6.4420916138968E-25"
                    izz="3.34755925557046E-07" />
            </inertial>
            <visual>
                <origin xyz="0 0 0" rpy="0 0 0" />
                <geometry>
                    <mesh filename="package://upros_description/meshes/W2C/wheel_A_Link.STL" />
                </geometry>
                <material name="">
                    <color rgba="0.752941176470588 1 1 1" />
                </material>
            </visual>
            <collision>
                <origin xyz="0 0 0" rpy="0 0 0" />
                <geometry>
                    <mesh filename="package://upros_description/meshes/W2C/wheel_A_Link.STL" />
                </geometry>
            </collision>
        </link>
        <joint name="back_joint" type="continuous">
            <origin xyz="-0.0859999999999998 0 -0.0575" rpy="0 0 0" />
            <parent link="base_link" />
            <child link="back_Link" />
            <axis xyz="1 1 1" />
        </joint>

    </xacro:macro>

</robot>