<?xml version="1.0" ?>
<!-- =================================================================================== -->
<!-- |    This document was autogenerated by xacro from /home/noodles/bash/upros_class_code/src/s2a_description/urdf/s2a_arm.xacro | -->
<!-- |    EDITING THIS FILE BY HAND IS NOT RECOMMENDED                                 | -->
<!-- =================================================================================== -->
<robot name="s2a_arm">
    <link name="base_footprint" />
    <link name="arm_base_link">
        <inertial>
            <origin rpy="0 0 0" xyz="-1.7947E-07 -0.0018392 0.042093" />
            <mass value="14.14029" />
            <inertia ixx="0.00016721" ixy="-1.4903E-10" ixz="-3.0653E-10" iyy="0.00016551" iyz="-2.4534E-06" izz="0.0001699" />
        </inertial>
        <visual>
            <origin rpy="0 0 0" xyz="0 0 0" />
            <geometry>
                <mesh filename="package://s2a_description/meshes/arm/arm_base_link.STL" />
            </geometry>
            <material name="">
                <color rgba="0.2 0.2 0.2 1" />
            </material>
        </visual>
        <collision>
            <origin rpy="0 0 0" xyz="0 0 0" />
            <geometry>
                <mesh filename="package://s2a_description/meshes/arm/arm_base_link.STL" />
            </geometry>
        </collision>
    </link>
    <joint name="arm_joint" type="fixed">
        <origin rpy="0 0 0" xyz="0.0 0.0 0.0" />
        <parent link="base_footprint" />
        <child link="arm_base_link" />
        <axis xyz="0 0 0" />
    </joint>
    <link name="link_1">
        <inertial>
            <origin rpy="0 0 0" xyz="0.00015999 -3.7029E-07 0.0067201" />
            <mass value="0.068148" />
            <inertia ixx="3.0609E-05" ixy="-5.9099E-11" ixz="-1.3841E-07" iyy="3.6584E-05" iyz="4.9301E-10" izz="2.3547E-05" />
        </inertial>
        <visual>
            <origin rpy="0 0 0" xyz="0 0 0" />
            <geometry>
                <mesh filename="package://s2a_description/meshes/arm/link_1.STL" />
            </geometry>
            <material name="">
                <color rgba="0.2 0.2 0.2 1" />
            </material>
        </visual>
        <collision>
            <origin rpy="0 0 0" xyz="0 0 0" />
            <geometry>
                <mesh filename="package://s2a_description/meshes/arm/link_1.STL" />
            </geometry>
        </collision>
    </link>
    <joint name="joint_1" type="revolute">
        <origin rpy="0 0 0" xyz="0 0 0.072247" />
        <parent link="arm_base_link" />
        <child link="link_1" />
        <axis xyz="0 0 1" />
        <limit effort="50" lower="-1.8" upper="1.8" velocity="2" />
    </joint>
    <link name="link_2">
        <inertial>
            <origin rpy="0 0 0" xyz="0.028477 -5.0821E-07 0.038913" />
            <mass value="0.049654" />
            <inertia ixx="1.8351E-05" ixy="-6.0792E-11" ixz="-6.4071E-08" iyy="3.1671E-05" iyz="3.6197E-10" izz="1.6517E-05" />
        </inertial>
        <visual>
            <origin rpy="0 0 0" xyz="0 0 0" />
            <geometry>
                <mesh filename="package://s2a_description/meshes/arm/link_2.STL" />
            </geometry>
            <material name="">
                <color rgba="0.2 0.2 0.2 1" />
            </material>
        </visual>
        <collision>
            <origin rpy="0 0 0" xyz="0 0 0" />
            <geometry>
                <mesh filename="package://s2a_description/meshes/arm/link_2.STL" />
            </geometry>
        </collision>
    </link>
    <joint name="joint_2" type="revolute">
        <origin rpy="0 0 0" xyz="-0.028151 0 0.034" />
        <parent link="link_1" />
        <child link="link_2" />
        <axis xyz="1 0 0" />
        <limit effort="50" lower="-1.8" upper="1.8" velocity="3" />
    </joint>
    <link name="link_3">
        <inertial>
            <origin rpy="0 0 0" xyz="0.028363 -4.679E-07 0.054247" />
            <mass value="0.053931" />
            <inertia ixx="3.1912E-05" ixy="-6.0429E-11" ixz="-9.8626E-08" iyy="4.873E-05" iyz="4.797E-10" izz="2.0341E-05" />
        </inertial>
        <visual>
            <origin rpy="0 0 0" xyz="0 0 0" />
            <geometry>
                <mesh filename="package://s2a_description/meshes/arm/link_3.STL" />
            </geometry>
            <material name="">
                <color rgba="0.2 0.2 0.2 1" />
            </material>
        </visual>
        <collision>
            <origin rpy="0 0 0" xyz="0 0 0" />
            <geometry>
                <mesh filename="package://s2a_description/meshes/arm/link_3.STL" />
            </geometry>
        </collision>
    </link>
    <joint name="joint_3" type="revolute">
        <origin rpy="0 0 0" xyz="9.8516E-05 0 0.061" />
        <parent link="link_2" />
        <child link="link_3" />
        <axis xyz="1 0 0" />
        <limit effort="50" lower="-1.8" upper="1.8" velocity="3" />
    </joint>
    <link name="link_4">
        <inertial>
            <origin rpy="0 0 0" xyz="0.028255 -0.0047504 0.06611" />
            <mass value="0.10537" />
            <inertia ixx="9.6221E-05" ixy="-3.6252E-10" ixz="2.7529E-08" iyy="7.3811E-05" iyz="7.9136E-06" izz="6.9537E-05" />
        </inertial>
        <visual>
            <origin rpy="0 0 0" xyz="0 0 0" />
            <geometry>
                <mesh filename="package://s2a_description/meshes/arm/link_4.STL" />
            </geometry>
            <material name="">
                <color rgba="0.2 0.2 0.2 1" />
            </material>
        </visual>
        <collision>
            <origin rpy="0 0 0" xyz="0 0 0" />
            <geometry>
                <mesh filename="package://s2a_description/meshes/arm/link_4.STL" />
            </geometry>
        </collision>
    </link>
    <joint name="joint_4" type="revolute">
        <origin rpy="0 0 0" xyz="0 0 0.081" />
        <parent link="link_3" />
        <child link="link_4" />
        <axis xyz="1 0 0" />
        <limit effort="50" lower="-1.8" upper="1.8" velocity="3" />
    </joint>
    <link name="link_5">
        <inertial>
            <origin rpy="0 0 0" xyz="4.4212E-05 0.0041269 0.025698" />
            <mass value="0.098063" />
            <inertia ixx="3.7917E-05" ixy="1.4713E-07" ixz="-1.1994E-07" iyy="5.5952E-05" iyz="2.3438E-06" izz="5.2518E-05" />
        </inertial>
        <visual>
            <origin rpy="0 0 0" xyz="0 0 0" />
            <geometry>
                <mesh filename="package://s2a_description/meshes/arm/link_5.STL" />
            </geometry>
            <material name="">
                <color rgba="0.2 0.2 0.2 1" />
            </material>
        </visual>
        <collision>
            <origin rpy="0 0 0" xyz="0 0 0" />
            <geometry>
                <mesh filename="package://s2a_description/meshes/arm/link_5.STL" />
            </geometry>
        </collision>
    </link>
    <joint name="joint_5" type="revolute">
        <origin rpy="0 0 0" xyz="0.02825 0 0.0975" />
        <parent link="link_4" />
        <child link="link_5" />
        <axis xyz="0 0 -1" />
        <limit effort="50" lower="-1.8" upper="1.8" velocity="3" />
    </joint>
    <link name="gripper_center_link">
        <visual>
            <geometry>
                <box size="0.05 0.05 0.0001" />
            </geometry>
            <origin rpy="0.0 0.0 0.0" xyz="0.0 0.0 0.01" />
            <material name="">
                <color rgba="0.898039215686275 0.917647058823529 0.929411764705882 1" />
            </material>
        </visual>
        <collision>
            <geometry>
                <box size="0.05 0.05 0.01" />
            </geometry>
            <origin rpy="0.0 0.0 0.0" xyz="0.0 0.0 0.01" />
        </collision>
        <inertial>
            <mass value="0.00000001" />
            <inertia ixx="0.0001" ixy="0.0" ixz="0.0" iyy="0.0001" iyz="0.0" izz="0.0001" />
            <origin xyz="0 0 0" rpy="0 0 0" />
        </inertial>
    </link>
    <joint name="gripper_centor_joint" type="fixed">
        <parent link="link_5" />
        <child link="gripper_center_link" />
        <origin rpy="0.0 0.0 0.0" xyz="0.0 0.0 0.08" />
    </joint>
    <link name="claw_link_1">
        <inertial>
            <origin rpy="0 0 0" xyz="0.0054256 -0.015308 0.019147" />
            <mass value="0.018231" />
            <inertia ixx="6.9914E-06" ixy="-3.7017E-08" ixz="1.3043E-06" iyy="6.7797E-06" iyz="4.9174E-08" izz="2.5386E-06" />
        </inertial>
        <visual>
            <origin rpy="0 0 0" xyz="0 0 0" />
            <geometry>
                <mesh filename="package://s2a_description/meshes/arm/claw_link_1.STL" />
            </geometry>
            <material name="">
                <color rgba="0.2 0.2 0.2 1" />
            </material>
        </visual>
        <collision>
            <origin rpy="0 0 0" xyz="0 0 0" />
            <geometry>
                <mesh filename="package://s2a_description/meshes/arm/claw_link_1.STL" />
            </geometry>
        </collision>
    </link>
    <joint name="claw_joint_1" type="fixed">
        <origin rpy="0 0 0" xyz="-0.028 0.015 0.0462" />
        <parent link="link_5" />
        <child link="claw_link_1" />
        <axis xyz="0 -1 0" />
        <limit effort="10" lower="-1.5" upper="1.5" velocity="3" />
    </joint>
    <link name="claw_link_2">
        <inertial>
            <origin rpy="0 0 0" xyz="-0.0054256 -0.015308 0.019147" />
            <mass value="0.018231" />
            <inertia ixx="6.9914E-06" ixy="3.7016E-08" ixz="-1.3043E-06" iyy="6.7797E-06" iyz="4.9173E-08" izz="2.5386E-06" />
        </inertial>
        <visual>
            <origin rpy="0 0 0" xyz="0 0 0" />
            <geometry>
                <mesh filename="package://s2a_description/meshes/arm/claw_link_2.STL" />
            </geometry>
            <material name="">
                <color rgba="0.2 0.2 0.2 1" />
            </material>
        </visual>
        <collision>
            <origin rpy="0 0 0" xyz="0 0 0" />
            <geometry>
                <mesh filename="package://s2a_description/meshes/arm/claw_link_2.STL" />
            </geometry>
        </collision>
    </link>
    <joint name="claw_joint_2" type="fixed">
        <origin rpy="0 0 0" xyz="0.027609 0.015 0.0462" />
        <parent link="link_5" />
        <child link="claw_link_2" />
        <axis xyz="0 -1 0" />
        <limit effort="10" lower="-1.5" upper="1.5" velocity="3" />
    </joint>
    <!-- ros_control plugin -->
    <gazebo>
        <plugin filename="libgazebo_ros_control.so" name="gazebo_ros_control">
            <robotNamespace>/</robotNamespace>
            <robotSimType>gazebo_ros_control/DefaultRobotHWSim</robotSimType>
            <legacyModeNS>true</legacyModeNS>
        </plugin>
    </gazebo>
    <transmission name="tran1">
        <type>transmission_interface/SimpleTransmission</type>
        <joint name="joint_1">
            <hardwareInterface>hardware_interface/PositionJointInterface</hardwareInterface>
        </joint>
        <actuator name="motor1">
            <hardwareInterface>hardware_interface/PositionJointInterface</hardwareInterface>
            <mechanicalReduction>1</mechanicalReduction>
        </actuator>
    </transmission>
    <transmission name="tran1">
        <type>transmission_interface/SimpleTransmission</type>
        <joint name="joint_2">
            <hardwareInterface>hardware_interface/PositionJointInterface</hardwareInterface>
        </joint>
        <actuator name="motor1">
            <hardwareInterface>hardware_interface/PositionJointInterface</hardwareInterface>
            <mechanicalReduction>1</mechanicalReduction>
        </actuator>
    </transmission>
    <transmission name="tran1">
        <type>transmission_interface/SimpleTransmission</type>
        <joint name="joint_3">
            <hardwareInterface>hardware_interface/PositionJointInterface</hardwareInterface>
        </joint>
        <actuator name="motor1">
            <hardwareInterface>hardware_interface/PositionJointInterface</hardwareInterface>
            <mechanicalReduction>1</mechanicalReduction>
        </actuator>
    </transmission>
    <transmission name="tran1">
        <type>transmission_interface/SimpleTransmission</type>
        <joint name="joint_4">
            <hardwareInterface>hardware_interface/PositionJointInterface</hardwareInterface>
        </joint>
        <actuator name="motor1">
            <hardwareInterface>hardware_interface/PositionJointInterface</hardwareInterface>
            <mechanicalReduction>1</mechanicalReduction>
        </actuator>
    </transmission>
    <transmission name="tran1">
        <type>transmission_interface/SimpleTransmission</type>
        <joint name="joint_5">
            <hardwareInterface>hardware_interface/PositionJointInterface</hardwareInterface>
        </joint>
        <actuator name="motor1">
            <hardwareInterface>hardware_interface/PositionJointInterface</hardwareInterface>
            <mechanicalReduction>1</mechanicalReduction>
        </actuator>
    </transmission>
    <transmission name="tran1">
        <type>transmission_interface/SimpleTransmission</type>
        <joint name="claw_joint_1">
            <hardwareInterface>hardware_interface/PositionJointInterface</hardwareInterface>
        </joint>
        <actuator name="motor1">
            <hardwareInterface>hardware_interface/PositionJointInterface</hardwareInterface>
            <mechanicalReduction>1</mechanicalReduction>
        </actuator>
    </transmission>
    <transmission name="tran1">
        <type>transmission_interface/SimpleTransmission</type>
        <joint name="claw_joint_2">
            <hardwareInterface>hardware_interface/PositionJointInterface</hardwareInterface>
        </joint>
        <actuator name="motor1">
            <hardwareInterface>hardware_interface/PositionJointInterface</hardwareInterface>
            <mechanicalReduction>1</mechanicalReduction>
        </actuator>
    </transmission>
</robot>

